<?xml version="1.0" encoding="utf-8"?>
<robot name="robstride">
  <link name="base"/>
  <joint name="right_fixed" type="fixed">
    <origin rpy="0 0 0" xyz="0 0 0"/>
    <parent link="base"/>
    <child link="right_base_link"/>
  </joint>
  <link name="right_base_link">
    <inertial>
      <origin xyz="-0.00025799 -0.029883 0.7" rpy="0 0 0" />
      <mass value="1.6258" />
      <inertia ixx="0.0017026" ixy="-3.9333E-08" ixz="-3.604E-06" iyy="0.0027764" iyz="2.0132E-06" izz="0.0016415" />
    </inertial>
    <visual>
      <origin xyz="0 0 0" rpy="0 0 0" />
      <geometry>
        <mesh filename="right_base_link.STL" />
      </geometry>
      <material name="">
        <color rgba="0.75294 0.75294 0.75294 1" />
      </material>
    </visual>
    <collision>
      <origin xyz="0 0 0" rpy="0 0 0" />
      <geometry>
        <mesh filename="right_base_link.STL" />
      </geometry>
    </collision>
  </link>
  <link name="right_link1">
    <inertial>
      <origin xyz="-0.0060597 -0.00033237 0.064283" rpy="0 0 0" />
      <mass value="1.6394" />
      <inertia ixx="0.0028237" ixy="1.1023E-05" ixz="4.3224E-05" iyy="0.0017259" iyz="-2.3694E-05" izz="0.0017317" />
    </inertial>
    <visual>
      <origin xyz="0 0 0" rpy="0 0 0" />
      <geometry>
        <mesh filename="right_link1.STL" />
      </geometry>
      <material name="">
        <color rgba="0.75294 0.75294 0.75294 1" />
      </material>
    </visual>
    <collision>
      <origin xyz="0 0 0" rpy="0 0 0" />
      <geometry>
        <mesh filename="right_link1.STL" />
      </geometry>
    </collision>
  </link>
  <joint name="r_joint1" type="revolute">
    <origin xyz="0 -0.0675 0" rpy="1.5708 0 0" />
    <parent link="right_base_link" />
    <child link="right_link1" />
    <axis xyz="0 0 -1" />
    <limit lower="-2.93" upper="1.83" effort="60" velocity="18.84" />
  </joint>
  <link name="right_link2">
    <inertial>
      <origin xyz="0.00061246 -0.095278 -0.026226" rpy="0 0 0" />
      <mass value="1.1072" />
      <inertia ixx="0.00081879" ixy="-4.4518E-08" ixz="-4.4531E-07" iyy="0.0011274" iyz="-8.5582E-05" izz="0.00084188" />
    </inertial>
    <visual>
      <origin xyz="0 0 0" rpy="0 0 0" />
      <geometry>
        <mesh filename="right_link2.STL" />
      </geometry>
      <material name="">
        <color rgba="0.75294 0.75294 0.75294 1" />
      </material>
    </visual>
    <collision>
      <origin xyz="0 0 0" rpy="0 0 0" />
      <geometry>
        <mesh filename="right_link2.STL" />
      </geometry>
    </collision>
  </link>
  <joint name="r_joint2" type="revolute">
    <origin xyz="0.02775 0 0.07" rpy="-1.5708 0 -1.5708" />
    <parent link="right_link1" />
    <child link="right_link2" />
    <axis xyz="0 0 -1" />
    <limit lower="-1.84" upper="1.4" effort="60" velocity="18.84" />
  </joint>
  <link name="right_link3">
    <inertial>
      <origin xyz="-0.0077183 -0.023944 0.13982" rpy="0 0 0" />
      <mass value="1.161" />
      <inertia ixx="0.0012382" ixy="-4.4631E-08" ixz="6.3046E-06" iyy="0.00077359" iyz="1.5563E-05" izz="0.00064504" />
    </inertial>
    <visual>
      <origin xyz="0 0 0" rpy="0 0 0" />
      <geometry>
        <mesh filename="right_link3.STL" />
      </geometry>
      <material name="">
        <color rgba="0.75294 0.75294 0.75294 1" />
      </material>
    </visual>
    <collision>
      <origin xyz="0 0 0" rpy="0 0 0" />
      <geometry>
        <mesh filename="right_link3.STL" />
      </geometry>
    </collision>
  </link>
  <joint name="r_joint3" type="revolute">
    <origin xyz="0 -0.139 -0.02775" rpy="1.5708 0 0" />
    <parent link="right_link2" />
    <child link="right_link3" />
    <axis xyz="0 0 -1" />
    <limit lower="-1.75" upper="2.55" effort="25" velocity="18.84" />
  </joint>
  <link name="right_link4">
    <inertial>
      <origin xyz="-0.024501 -0.086748 -0.024903" rpy="0 0 0" />
      <mass value="0.50959" />
      <inertia ixx="0.00025117" ixy="-1.037E-05" ixz="-1.2834E-06" iyy="0.00036316" iyz="-4.681E-06" izz="0.00028817" />
    </inertial>
    <visual>
      <origin xyz="0 0 0" rpy="0 0 0" />
      <geometry>
        <mesh filename="right_link4.STL" />
      </geometry>
      <material name="">
        <color rgba="0.75294 0.75294 0.75294 1" />
      </material>
    </visual>
    <collision>
      <origin xyz="0 0 0" rpy="0 0 0" />
      <geometry>
        <mesh filename="right_link4.STL" />
      </geometry>
    </collision>
  </link>
  <joint name="r_joint4" type="revolute">
    <origin xyz="0.02925 -0.025 0.15996" rpy="-1.5708 0 -1.5708" />
    <parent link="right_link3" />
    <child link="right_link4" />
    <axis xyz="0 0 -1" />
    <limit lower="0.0" upper="1.9" effort="25" velocity="18.84" />
  </joint>
  <link name="right_link5">
    <inertial>
      <origin xyz="1.1143E-05 -0.018712 0.079844" rpy="0 0 0" />
      <mass value="0.62009" />
      <inertia ixx="0.00041399" ixy="-8.164E-08" ixz="-2.4911E-09" iyy="0.00045649" iyz="2.3996E-06" izz="0.00018831" />
    </inertial>
    <visual>
      <origin xyz="0 0 0" rpy="0 0 0" />
      <geometry>
        <mesh filename="right_link5.STL" />
      </geometry>
      <material name="">
        <color rgba="0.75294 0.75294 0.75294 1" />
      </material>
    </visual>
    <collision>
      <origin xyz="0 0 0" rpy="0 0 0" />
      <geometry>
        <mesh filename="right_link5.STL" />
      </geometry>
    </collision>
  </link>
  <joint name="r_joint5" type="revolute">
    <origin xyz="-0.025 -0.12396 -0.028" rpy="1.5708 -1.5708 0" />
    <parent link="right_link4" />
    <child link="right_link5" />
    <axis xyz="0 0 -1" />
    <limit lower="-2.1" upper="2.4" effort="7" velocity="28" />
  </joint>
  <link name="right_link6">
    <inertial>
      <origin xyz="-0.00034528 -0.00032447 -0.03202" rpy="0 0 0" />
      <mass value="0.34836" />
      <inertia ixx="0.00014598" ixy="1.3757E-07" ixz="8.1641E-08" iyy="0.00012518" iyz="-2.491E-09" izz="0.00010598" />
    </inertial>
    <visual>
      <origin xyz="0 0 0" rpy="0 0 0" />
      <geometry>
        <mesh filename="right_link6.STL" />
      </geometry>
      <material name="">
        <color rgba="0.75294 0.75294 0.75294 1" />
      </material>
    </visual>
    <collision>
      <origin xyz="0 0 0" rpy="0 0 0" />
      <geometry>
        <mesh filename="right_link6.STL" />
      </geometry>
    </collision>
  </link>
  <joint name="r_joint6" type="revolute">
    <origin xyz="0 -0.032 0.17" rpy="1.5708 0 0" />
    <parent link="right_link5" />
    <child link="right_link6" />
    <axis xyz="0 0 -1" />
    <limit lower="-1.4" upper="1.4" effort="5.5" velocity="25" />
  </joint>
  <link name="right_link7">
    <inertial>
      <origin xyz="-2.7286E-13 0.037121 -0.015017" rpy="0 0 0" />
      <mass value="0.043226" />
      <inertia ixx="1.8703E-05" ixy="-1.4456E-19" ixz="1.0593E-19" iyy="9.6135E-06" iyz="4.2677E-06" izz="1.783E-05" />
    </inertial>
    <visual>
      <origin xyz="0 0 0" rpy="0 0 0" />
      <geometry>
        <mesh filename="right_link7.STL" />
      </geometry>
      <material name="">
        <color rgba="0.75294 0.75294 0.75294 1" />
      </material>
    </visual>
    <collision>
      <origin xyz="0 0 0" rpy="0 0 0" />
      <geometry>
        <mesh filename="right_link7.STL" />
      </geometry>
    </collision>
  </link>
  <joint name="r_joint7" type="revolute">
    <origin xyz="-0.03 0 -0.032" rpy="0 -1.5708 0" />
    <parent link="right_link6" />
    <child link="right_link7" />
    <axis xyz="0 0 -1" />
    <limit lower="-0.68" upper="0.68" effort="5.5" velocity="25" />
  </joint>
  <link name="right_ee"/>
  <joint name="r_jointee_fixed" type="fixed">
    <origin xyz="0 0 -0.028" rpy="0 0 1.57"/>
    <parent link="right_link7"/>
    <child link="right_ee"/>
  </joint>
</robot>